Workbook

Sheet Label
A1: VRT COMMENT | B1: Detection
A2: https://github.com/storybookjs/storybook/pull/20712#discussion_r1083565846 | B2: Focus Does Not Work
A3: https://github.com/storybookjs/storybook/pull/20712#discussion_r1083724374 | B3: OutOfScope: Duplicates
A4: https://github.com/ni/nimble/pull/966#discussion_r1074023214 | B4: Size of Page/Header Changed
A5: https://github.com/guardian/dotcom-rendering/pull/6954#issuecomment-1383873154 | B5: OutOfScope: Cannot access
A6: https://github.com/GCTC-NTGC/gc-digital-talent/pull/5740#issuecomment-1440357711 | B6: Text Size Changed
A7: https://github.com/storybookjs/storybook/pull/20995#issuecomment-1426807019 | B7: OutOfScope: Duplicates
A8: https://github.com/guardian/dotcom-rendering/pull/7128#issuecomment-1422355751 | B8: Layout Shifted
A9: https://github.com/guardian/dotcom-rendering/pull/7128#issuecomment-1422375286 | B9: OutOfScope: Duplicates
A10: https://github.com/guardian/dotcom-rendering/pull/7128#issuecomment-1422416345 | B10: OutOfScope: Duplicates
A11: https://github.com/ithaka/pharos/pull/503#discussion_r1146494323 | B11: Border Disappeared
A12: https://github.com/adobe/react-spectrum/pull/4243#issuecomment-1481577294 | B12: OutOfScope: New Story
A13: https://github.com/NeurodataWithoutBorders/nwb-guide/pull/74#issuecomment-1486132202 | B13: Image Replaced | C13: Layout Changed
A14: https://github.com/NeurodataWithoutBorders/nwb-guide/pull/74#issuecomment-1486151336 | B14: OutOfScope: Duplicates
A15: https://github.com/seek-oss/braid-design-system/pull/1240#discussion_r1127264221 | B15: Text Disappeared | C15: New Contents
A16: https://github.com/contentful/forma-36/pull/2436#issuecomment-1482782327 | B16: Layout Shifted
A17: https://github.com/contentful/forma-36/pull/2436#issuecomment-1485049856 | B17: OutOfScope: Duplicates
A18: https://github.com/contentful/forma-36/pull/2430#issuecomment-1468376389 | B18: Undefined/Wrong State is Shown
A19: https://github.com/sbb-design-systems/lyne-components/pull/1691#discussion_r1155937820 | B19: OutOfScope: New Story
A20: https://github.com/livechat/design-system/pull/518#issuecomment-1513081507 | B20: Default State is Changed
A21: https://github.com/coder/coder/pull/7210#issuecomment-1523711377 | B21: OutOfScope: New Story
A22: https://github.com/coder/coder/pull/7210#issuecomment-1523829146 | B22: OutOfScope: Duplicates
A23: https://github.com/forkfacts/forkfacts-v2/pull/26#discussion_r1156498711 | B23: OutOfScope: Cannot access
A24: https://github.com/storybookjs/storybook/pull/22336#issuecomment-1576578560 | B24: OutOfScope: New Story
A25: https://github.com/ForgeRock/forgerock-web-login-framework/pull/121#issuecomment-1582606514 | B25: OutOfScope: New Story
A26: https://github.com/ForgeRock/forgerock-web-login-framework/pull/121#issuecomment-1582829867 | B26: OutOfScope: Duplicates
A27: https://github.com/danskernesdigitalebibliotek/dpl-design-system/pull/239#issuecomment-1590831197 | B27: OutOfScope: Duplicates
... A94: https://github.com/NeurodataWithoutBorders/nwb-guide/pull/674#issuecomment-1999943078 | B94: Layout Shifted
A95: https://github.com/guardian/dotcom-rendering/pull/10864#issuecomment-2017657371 | B95: New Text | C95: Text Disappeared
A96: https://github.com/wellcomecollection/wellcomecollection.org/pull/10792#issuecomment-2061398319 | B96: Size of Page/Header Changed
A97: https://github.com/ethereum/ethereum-org-website/pull/12639#issuecomment-2035787922 | B97: Image Replaced
A98: https://github.com/ethereum/ethereum-org-website/pull/12639#issuecomment-2045255946 | B98: OutOfScope: Duplicates
A99: https://github.com/coder/coder/pull/13031#issuecomment-2072113477 | B99: OutOfScope: Duplicates
A100: https://github.com/recharts/recharts/pull/4441#issuecomment-2063787042 | B100: Size of Page/Header Changed
A101: https://github.com/appsmithorg/appsmith/pull/32857#issuecomment-2071595653 | B101: Box Color Changed
A102: https://github.com/kufu/smarthr-ui/pull/4626#discussion_r1587350621 | B102: Focus Does Not Work
A103: https://github.com/misskey-dev/misskey/pull/13830#issuecomment-2155886151 | B103: Specific Items are Mis-aligned
A104: https://github.com/cloudblue/connect-ui-toolkit/pull/92#issuecomment-2117027142 | B104: OutOfScope: Chromatic Error
A105: https://github.com/cloudblue/connect-ui-toolkit/pull/92#issuecomment-2117397544 | B105: OutOfScope: Duplicates
A106: https://github.com/danskernesdigitalebibliotek/dpl-design-system/pull/650#issuecomment-2153175265 | B106: Border Color Changed
...

Sheet シート7
A1: https://github.com/mswjs/msw-storybook-addon/pull/22#discussion_r602729163 | B1: =IF(COUNTIF(C:C, A1) = 0, "no", IF(COUNTIF(C:C, A1) = 1, "OK", "duplicate")) -> OK | C1: https://github.com/storybookjs/storybook/pull/20712#discussion_r1083565846 | E1: =IF(COUNTIF(A:A, C1) = 0, "no", IF(COUNTIF(A:A, C1) = 1, "OK", "duplicate")) -> OK | G1: https://github.com/storybookjs/storybook/pull/20712#discussion_r1083565846 | H1: =IF(COUNTIF(A:A, G1) = 0, "no", IF(COUNTIF(A:A, G1) = 1, "OK", "duplicate")) -> OK | I1: {=_xludf.XLOOKUP(G1,Label!$A$2:$A$309, Label!$B$2:$B$309)} -> #NAME? | J1: {=_xludf.XLOOKUP(G1,Label!$A$2:$A$309, Label!$C$2:$C$309)} -> #NAME?
A2: https://github.com/storybookjs/storybook/pull/14528#issuecomment-818063376 | B2: =IF(COUNTIF(C:C, A2) = 0, "no", IF(COUNTIF(C:C, A2) = 1, "OK", "duplicate")) -> OK | C2: https://github.com/storybookjs/storybook/pull/20712#discussion_r1083724374 | E2: =IF(COUNTIF(A:A, C2) = 0, "no", IF(COUNTIF(A:A, C2) = 1, "OK", "duplicate")) -> OK | G2: https://github.com/storybookjs/storybook/pull/20712#discussion_r1083724374 | H2: =IF(COUNTIF(A:A, G2) = 0, "no", IF(COUNTIF(A:A, G2) = 1, "OK", "duplicate")) -> OK | I2: {=_xludf.XLOOKUP(G2,Label!$A$2:$A$309, Label!$B$2:$B$309)} -> #NAME? | J2: {=_xludf.XLOOKUP(G2,Label!$A$2:$A$309, Label!$C$2:$C$309)} -> #NAME?
A3: https://github.com/storybookjs/storybook/pull/15080#issuecomment-850596423 | B3: =IF(COUNTIF(C:C, A3) = 0, "no", IF(COUNTIF(C:C, A3) = 1, "OK", "duplicate")) -> OK | C3: https://github.com/ni/nimble/pull/966#discussion_r1074023214 | E3: =IF(COUNTIF(A:A, C3) = 0, "no", IF(COUNTIF(A:A, C3) = 1, "OK", "duplicate")) -> OK | G3: https://github.com/ni/nimble/pull/966#discussion_r1074023214 | H3: =IF(COUNTIF(A:A, G3) = 0, "no", IF(COUNTIF(A:A, G3) = 1, "OK", "duplicate")) -> OK | I3: {=_xludf.XLOOKUP(G3,Label!$A$2:$A$309, Label!$B$2:$B$309)} -> #NAME? | J3: {=_xludf.XLOOKUP(G3,Label!$A$2:$A$309, Label!$C$2:$C$309)} -> #NAME?
A4: https://github.com/storybookjs/storybook/pull/15080#issuecomment-850776321 | B4: =IF(COUNTIF(C:C, A4) = 0, "no", IF(COUNTIF(C:C, A4) = 1, "OK", "duplicate")) -> OK | C4: https://github.com/guardian/dotcom-rendering/pull/6954#issuecomment-1383873154 | E4: =IF(COUNTIF(A:A, C4) = 0, "no", IF(COUNTIF(A:A, C4) = 1, "OK", "duplicate")) -> OK | G4: https://github.com/guardian/dotcom-rendering/pull/6954#issuecomment-1383873154 | H4: =IF(COUNTIF(A:A, G4) = 0, "no", IF(COUNTIF(A:A, G4) = 1, "OK", "duplicate")) -> OK | I4: {=_xludf.XLOOKUP(G4,Label!$A$2:$A$309, Label!$B$2:$B$309)} -> #NAME? | J4: {=_xludf.XLOOKUP(G4,Label!$A$2:$A$309, Label!$C$2:$C$309)} -> #NAME?
A5: https://github.com/storybookjs/storybook/pull/15080#issuecomment-870014559 | B5: =IF(COUNTIF(C:C, A5) = 0, "no", IF(COUNTIF(C:C, A5) = 1, "OK", "duplicate")) -> OK | C5: https://github.com/GCTC-NTGC/gc-digital-talent/pull/5740#issuecomment-1440357711 | E5: =IF(COUNTIF(A:A, C5) = 0, "no", IF(COUNTIF(A:A, C5) = 1, "OK", "duplicate")) -> OK | G5: https://github.com/GCTC-NTGC/gc-digital-talent/pull/5740#issuecomment-1440357711 | H5: =IF(COUNTIF(A:A, G5) = 0, "no", IF(COUNTIF(A:A, G5) = 1, "OK", "duplicate")) -> OK | I5: {=_xludf.XLOOKUP(G5,Label!$A$2:$A$309, Label!$B$2:$B$309)} -> #NAME? | J5: {=_xludf.XLOOKUP(G5,Label!$A$2:$A$309, Label!$C$2:$C$309)} -> #NAME?
A6: https://github.com/nickooms/learnstorybook-design-system/pull/1#issuecomment-849190817 | B6: =IF(COUNTIF(C:C, A6) = 0, "no", IF(COUNTIF(C:C, A6) = 1, "OK", "duplicate")) -> OK | C6: https://github.com/storybookjs/storybook/pull/20995#issuecomment-1426807019 | E6: =IF(COUNTIF(A:A, C6) = 0, "no", IF(COUNTIF(A:A, C6) = 1, "OK", "duplicate")) -> OK | G6: https://github.com/storybookjs/storybook/pull/20995#issuecomment-1426807019 | H6: =IF(COUNTIF(A:A, G6) = 0, "no", IF(COUNTIF(A:A, G6) = 1, "OK", "duplicate")) -> OK | I6: {=_xludf.XLOOKUP(G6,Label!$A$2:$A$309, Label!$B$2:$B$309)} -> #NAME? | J6: {=_xludf.XLOOKUP(G6,Label!$A$2:$A$309, Label!$C$2:$C$309)} -> #NAME?
A7: https://github.com/adobe/react-spectrum/pull/2515#issuecomment-966653132 | B7: =IF(COUNTIF(C:C, A7) = 0, "no", IF(COUNTIF(C:C, A7) = 1, "OK", "duplicate")) -> OK | C7: https://github.com/guardian/dotcom-rendering/pull/7128#issuecomment-1422355751 | E7: =IF(COUNTIF(A:A, C7) = 0, "no", IF(COUNTIF(A:A, C7) = 1, "OK", "duplicate")) -> OK | G7: https://github.com/guardian/dotcom-rendering/pull/7128#issuecomment-1422355751 | H7: =IF(COUNTIF(A:A, G7) = 0, "no", IF(COUNTIF(A:A, G7) = 1, "OK", "duplicate")) -> OK | I7: {=_xludf.XLOOKUP(G7,Label!$A$2:$A$309, Label!$B$2:$B$309)} -> #NAME? | J7: {=_xludf.XLOOKUP(G7,Label!$A$2:$A$309, Label!$C$2:$C$309)} -> #NAME?
A8: https://github.com/adobe/react-spectrum/pull/2515#issuecomment-966699322 | B8: =IF(COUNTIF(C:C, A8) = 0, "no", IF(COUNTIF(C:C, A8) = 1, "OK", "duplicate")) -> OK | C8: https://github.com/guardian/dotcom-rendering/pull/7128#issuecomment-1422375286 | E8: =IF(COUNTIF(A:A, C8) = 0, "no", IF(COUNTIF(A:A, C8) = 1, "OK", "duplicate")) -> OK | G8: https://github.com/guardian/dotcom-rendering/pull/7128#issuecomment-1422375286 | H8: =IF(COUNTIF(A:A, G8) = 0, "no", IF(COUNTIF(A:A, G8) = 1, "OK", "duplicate")) -> OK | I8: {=_xludf.XLOOKUP(G8,Label!$A$2:$A$309, Label!$B$2:$B$309)} -> #NAME? | J8: {=_xludf.XLOOKUP(G8,Label!$A$2:$A$309, Label!$C$2:$C$309)} -> #NAME?
A9: https://github.com/ni/nimble/pull/260#discussion_r784963783 | B9: =IF(COUNTIF(C:C, A9) = 0, "no", IF(COUNTIF(C:C, A9) = 1, "OK", "duplicate")) -> OK | C9: https://github.com/guardian/dotcom-rendering/pull/7128#issuecomment-1422416345 | E9: =IF(COUNTIF(A:A, C9) = 0, "no", IF(COUNTIF(A:A, C9) = 1, "OK", "duplicate")) -> OK | G9: https://github.com/guardian/dotcom-rendering/pull/7128#issuecomment-1422416345 | H9: =IF(COUNTIF(A:A, G9) = 0, "no", IF(COUNTIF(A:A, G9) = 1, "OK", "duplicate")) -> OK | I9: {=_xludf.XLOOKUP(G9,Label!$A$2:$A$309, Label!$B$2:$B$309)} -> #NAME? | J9: {=_xludf.XLOOKUP(G9,Label!$A$2:$A$309, Label!$C$2:$C$309)} -> #NAME?
A10: https://github.com/Workday/canvas-kit/pull/1426#discussion_r787954027 | B10: =IF(COUNTIF(C:C, A10) = 0, "no", IF(COUNTIF(C:C, A10) = 1, "OK", "duplicate")) -> OK | C10: https://github.com/ithaka/pharos/pull/503#discussion_r1146494323 | E10: =IF(COUNTIF(A:A, C10) = 0, "no", IF(COUNTIF(A:A, C10) = 1, "OK", "duplicate")) -> OK | G10: https://github.com/ithaka/pharos/pull/503#discussion_r1146494323 | H10: =IF(COUNTIF(A:A, G10) = 0, "no", IF(COUNTIF(A:A, G10) = 1, "OK", "duplicate")) -> OK | I10: {=_xludf.XLOOKUP(G10,Label!$A$2:$A$309, Label!$B$2:$B$309)} -> #NAME? | J10: {=_xludf.XLOOKUP(G10,Label!$A$2:$A$309, Label!$C$2:$C$309)} -> #NAME?
A11: https://github.com/storybookjs/storybook/pull/17756#issuecomment-1246339422 | B11: =IF(COUNTIF(C:C, A11) = 0, "no", IF(COUNTIF(C:C, A11) = 1, "OK", "duplicate")) -> OK | C11: https://github.com/adobe/react-spectrum/pull/4243#issuecomment-1481577294 | E11: =IF(COUNTIF(A:A, C11) = 0, "no", IF(COUNTIF(A:A, C11) = 1, "OK", "duplicate")) -> OK | G11: https://github.com/adobe/react-spectrum/pull/4243#issuecomment-1481577294 | H11: =IF(COUNTIF(A:A, G11) = 0, "no", IF(COUNTIF(A:A, G11) = 1, "OK", "duplicate")) -> OK | I11: {=_xludf.XLOOKUP(G11,Label!$A$2:$A$309, Label!$B$2:$B$309)} -> #NAME? | J11: {=_xludf.XLOOKUP(G11,Label!$A$2:$A$309, Label!$C$2:$C$309)} -> #NAME?
A12: https://github.com/guardian/source/pull/1307#discussion_r836569925 | B12: =IF(COUNTIF(C:C, A12) = 0, "no", IF(COUNTIF(C:C, A12) = 1, "OK", "duplicate")) -> OK | C12: https://github.com/NeurodataWithoutBorders/nwb-guide/pull/74#issuecomment-1486132202 | E12: =IF(COUNTIF(A:A, C12) = 0, "no", IF(COUNTIF(A:A, C12) = 1, "OK", "duplicate")) -> OK | G12: https://github.com/NeurodataWithoutBorders/nwb-guide/pull/74#issuecomment-1486132202 | H12: =IF(COUNTIF(A:A, G12) = 0, "no", IF(COUNTIF(A:A, G12) = 1, "OK", "duplicate")) -> OK | I12: {=_xludf.XLOOKUP(G12,Label!$A$2:$A$309, Label!$B$2:$B$309)} -> #NAME? | J12: {=_xludf.XLOOKUP(G12,Label!$A$2:$A$309, Label!$C$2:$C$309)} -> #NAME?
... A310: https://github.com/chanzuckerberg/sci-components/pull/236#issuecomment-1215832526 | B310: =IF(COUNTIF(C:C, A310) = 0, "no", IF(COUNTIF(C:C, A310) = 1, "OK", "duplicate")) -> OK | C310: https://github.com/storybookjs/storybook/pull/14528#issuecomment-818063376 | E310: =IF(COUNTIF(A:A, C310) = 0, "no", IF(COUNTIF(A:A, C310) = 1, "OK", "duplicate")) -> OK | G310: https://github.com/department-of-veterans-affairs/component-library/pull/1487#issuecomment-2668874799 | H310: =IF(COUNTIF(A:A, G310) = 0, "no", IF(COUNTIF(A:A, G310) = 1, "OK", "duplicate")) -> OK | I310: {=_xludf.XLOOKUP(G310,Label!$A$2:$A$309, Label!$B$2:$B$309)} -> #NAME? | J310: {=_xludf.XLOOKUP(G310,Label!$A$2:$A$309, Label!$C$2:$C$309)} -> #NAME?
A311: https://github.com/tablecheck/tablekit/pull/122#issuecomment-1257712016 | B311: =IF(COUNTIF(C:C, A311) = 0, "no", IF(COUNTIF(C:C, A311) = 1, "OK", "duplicate")) -> no | C311: https://github.com/storybookjs/storybook/pull/15080#issuecomment-850596423 | E311: =IF(COUNTIF(A:A, C311) = 0, "no", IF(COUNTIF(A:A, C311) = 1, "OK", "duplicate")) -> OK | G311: https://github.com/opengovsg/isomer/pull/1144#discussion_r1974730734 | H311: =IF(COUNTIF(A:A, G311) = 0, "no", IF(COUNTIF(A:A, G311) = 1, "OK", "duplicate")) -> no | I311: {=_xludf.XLOOKUP(G311,Conflict!$A$2:$A$35,Conflict!$I$2:$I$35)} -> #NAME? | J311: {=_xludf.XLOOKUP(G311,Conflict!$A$2:$A$35,Conflict!$J$2:$J$35)} -> #NAME?
A312: https://github.com/chanzuckerberg/sci-components/pull/236#issuecomment-1215832526 | B312: =IF(COUNTIF(C:C, A312) = 0, "no", IF(COUNTIF(C:C, A312) = 1, "OK", "duplicate")) -> OK | C312: https://github.com/storybookjs/storybook/pull/15080#issuecomment-850776321 | E312: =IF(COUNTIF(A:A, C312) = 0, "no", IF(COUNTIF(A:A, C312) = 1, "OK", "duplicate")) -> OK | G312: https://github.com/Esri/calcite-design-system/pull/11759#issuecomment-2738116384 | H312: =IF(COUNTIF(A:A, G312) = 0, "no", IF(COUNTIF(A:A, G312) = 1, "OK", "duplicate")) -> no | I312: {=_xludf.XLOOKUP(G312,Conflict!$A$2:$A$35,Conflict!$I$2:$I$35)} -> #NAME? | J312: {=_xludf.XLOOKUP(G312,Conflict!$A$2:$A$35,Conflict!$J$2:$J$35)} -> #NAME?
A313: https://github.com/launchdarkly/launchpad-ui/pull/351#issuecomment-1242158688 | B313: =IF(COUNTIF(C:C, A313) = 0, "no", IF(COUNTIF(C:C, A313) = 1, "OK", "duplicate")) -> OK | C313: https://github.com/storybookjs/storybook/pull/15080#issuecomment-870014559 | E313: =IF(COUNTIF(A:A, C313) = 0, "no", IF(COUNTIF(A:A, C313) = 1, "OK", "duplicate")) -> OK | G313: https://github.com/openops-cloud/openops/pull/286#issuecomment-2750462330 | H313: =IF(COUNTIF(A:A, G313) = 0, "no", IF(COUNTIF(A:A, G313) = 1, "OK", "duplicate")) -> no | I313: {=_xludf.XLOOKUP(G313,Conflict!$A$2:$A$35,Conflict!$I$2:$I$35)} -> #NAME? | J313: {=_xludf.XLOOKUP(G313,Conflict!$A$2:$A$35,Conflict!$J$2:$J$35)} -> #NAME?
A314: https://github.com/storybookjs/storybook/pull/19189#issuecomment-1248920649 | B314: =IF(COUNTIF(C:C, A314) = 0, "no", IF(COUNTIF(C:C, A314) = 1, "OK", "duplicate")) -> OK | C314: https://github.com/nickooms/learnstorybook-design-system/pull/1#issuecomment-849190817 | E314: =IF(COUNTIF(A:A, C314) = 0, "no", IF(COUNTIF(A:A, C314) = 1, "OK", "duplicate")) -> OK | G314: https://github.com/temporalio/ui/pull/2599#issuecomment-2730449028 | H314: =IF(COUNTIF(A:A, G314) = 0, "no", IF(COUNTIF(A:A, G314) = 1, "OK", "duplicate")) -> no | I314: {=_xludf.XLOOKUP(G314,Conflict!$A$2:$A$35,Conflict!$I$2:$I$35)} -> #NAME? | J314: {=_xludf.XLOOKUP(G314,Conflict!$A$2:$A$35,Conflict!$J$2:$J$35)} -> #NAME?
A315: https://github.com/dpc-sdp/ripple-framework/pull/224#discussion_r970362124 | B315: =IF(COUNTIF(C:C, A315) = 0, "no", IF(COUNTIF(C:C, A315) = 1, "OK", "duplicate")) -> OK | C315: https://github.com/adobe/react-spectrum/pull/2515#issuecomment-966653132 | E315: =IF(COUNTIF(A:A, C315) = 0, "no", IF(COUNTIF(A:A, C315) = 1, "OK", "duplicate")) -> OK | G315: https://github.com/Khan/wonder-blocks/pull/2508#discussion_r2006483914 | H315: =IF(COUNTIF(A:A, G315) = 0, "no", IF(COUNTIF(A:A, G315) = 1, "OK", "duplicate")) -> no | I315: {=_xludf.XLOOKUP(G315,Conflict!$A$2:$A$35,Conflict!$I$2:$I$35)} -> #NAME? | J315: {=_xludf.XLOOKUP(G315,Conflict!$A$2:$A$35,Conflict!$J$2:$J$35)} -> #NAME?
A316: https://github.com/GCTC-NTGC/gc-digital-talent/pull/3865#issuecomment-1241109917 | B316: =IF(COUNTIF(C:C, A316) = 0, "no", IF(COUNTIF(C:C, A316) = 1, "OK", "duplicate")) -> OK | C316: https://github.com/adobe/react-spectrum/pull/2515#issuecomment-966699322 | E316: =IF(COUNTIF(A:A, C316) = 0, "no", IF(COUNTIF(A:A, C316) = 1, "OK", "duplicate")) -> OK | G316: https://github.com/Khan/wonder-blocks/pull/2508#discussion_r2008301713 | H316: =IF(COUNTIF(A:A, G316) = 0, "no", IF(COUNTIF(A:A, G316) = 1, "OK", "duplicate")) -> no | I316: {=_xludf.XLOOKUP(G316,Conflict!$A$2:$A$35,Conflict!$I$2:$I$35)} -> #NAME? | J316: {=_xludf.XLOOKUP(G316,Conflict!$A$2:$A$35,Conflict!$J$2:$J$35)} -> #NAME?
A317: https://github.com/storybookjs/components-marketing/pull/35#issuecomment-1242259347 | B317: =IF(COUNTIF(C:C, A317) = 0, "no", IF(COUNTIF(C:C, A317) = 1, "OK", "duplicate")) -> OK | C317: https://github.com/ni/nimble/pull/260#discussion_r784963783 | E317: =IF(COUNTIF(A:A, C317) = 0, "no", IF(COUNTIF(A:A, C317) = 1, "OK", "duplicate")) -> OK | G317: https://github.com/ory/elements/pull/371#discussion_r1977424201 | H317: =IF(COUNTIF(A:A, G317) = 0, "no", IF(COUNTIF(A:A, G317) = 1, "OK", "duplicate")) -> no | I317: {=_xludf.XLOOKUP(G317,Conflict!$A$2:$A$35,Conflict!$I$2:$I$35)} -> #NAME? | J317: {=_xludf.XLOOKUP(G317,Conflict!$A$2:$A$35,Conflict!$J$2:$J$35)} -> #NAME?
A318: https://github.com/storybookjs/storybook/pull/19181#issuecomment-1269341227 | B318: =IF(COUNTIF(C:C, A318) = 0, "no", IF(COUNTIF(C:C, A318) = 1, "OK", "duplicate")) -> OK | C318: https://github.com/Workday/canvas-kit/pull/1426#discussion_r787954027 | E318: =IF(COUNTIF(A:A, C318) = 0, "no", IF(COUNTIF(A:A, C318) = 1, "OK", "duplicate")) -> OK | G318: https://github.com/nl-design-system/denhaag/pull/1709#issuecomment-2703653274 | H318: =IF(COUNTIF(A:A, G318) = 0, "no", IF(COUNTIF(A:A, G318) = 1, "OK", "duplicate")) -> no | I318: {=_xludf.XLOOKUP(G318,Conflict!$A$2:$A$35,Conflict!$I$2:$I$35)} -> #NAME? | J318: {=_xludf.XLOOKUP(G318,Conflict!$A$2:$A$35,Conflict!$J$2:$J$35)} -> #NAME?
A319: https://github.com/chanzuckerberg/edu-design-system/pull/1322#discussion_r983726151 | B319: =IF(COUNTIF(C:C, A319) = 0, "no", IF(COUNTIF(C:C, A319) = 1, "OK", "duplicate")) -> OK | C319: https://github.com/storybookjs/storybook/pull/17756#issuecomment-1246339422 | E319: =IF(COUNTIF(A:A, C319) = 0, "no", IF(COUNTIF(A:A, C319) = 1, "OK", "duplicate")) -> OK | G319: https://github.com/adobe/spectrum-css/pull/3593#issuecomment-2693948041 | H319: =IF(COUNTIF(A:A, G319) = 0, "no", IF(COUNTIF(A:A, G319) = 1, "OK", "duplicate")) -> no | I319: {=_xludf.XLOOKUP(G319,Conflict!$A$2:$A$35,Conflict!$I$2:$I$35)} -> #NAME? | J319: {=_xludf.XLOOKUP(G319,Conflict!$A$2:$A$35,Conflict!$J$2:$J$35)} -> #NAME?
A320: https://github.com/chanzuckerberg/edu-design-system/pull/1322#discussion_r983737173 | B320: =IF(COUNTIF(C:C, A320) = 0, "no", IF(COUNTIF(C:C, A320) = 1, "OK", "duplicate")) -> OK | C320: https://github.com/guardian/source/pull/1307#discussion_r836569925 | E320: =IF(COUNTIF(A:A, C320) = 0, "no", IF(COUNTIF(A:A, C320) = 1, "OK", "duplicate")) -> OK | G320: https://github.com/nodejs/nodejs.org/pull/7638#issuecomment-2795597092 | H320: =IF(COUNTIF(A:A, G320) = 0, "no", IF(COUNTIF(A:A, G320) = 1, "OK", "duplicate")) -> no | I320: {=_xludf.XLOOKUP(G320,Conflict!$A$2:$A$35,Conflict!$I$2:$I$35)} -> #NAME? | J320: {=_xludf.XLOOKUP(G320,Conflict!$A$2:$A$35,Conflict!$J$2:$J$35)} -> #NAME?
A321: https://github.com/chanzuckerberg/edu-design-system/pull/1346#issuecomment-1279388288 | B321: =IF(COUNTIF(C:C, A321) = 0, "no", IF(COUNTIF(C:C, A321) = 1, "OK", "duplicate")) -> OK | C321: https://github.com/hackworthltd/primer-app/pull/332#issuecomment-1120316930 | E321: =IF(COUNTIF(A:A, C321) = 0, "no", IF(COUNTIF(A:A, C321) = 1, "OK", "duplicate")) -> OK | G321: https://github.com/Khan/wonder-blocks/pull/2563#discussion_r2049478574 | H321: =IF(COUNTIF(A:A, G321) = 0, "no", IF(COUNTIF(A:A, G321) = 1, "OK", "duplicate")) -> no | I321: {=_xludf.XLOOKUP(G321,Conflict!$A$2:$A$35,Conflict!$I$2:$I$35)} -> #NAME? | J321: {=_xludf.XLOOKUP(G321,Conflict!$A$2:$A$35,Conflict!$J$2:$J$35)} -> #NAME?
A322: https://github.com/chanzuckerberg/edu-design-system/pull/1346#issuecomment-1279399748 | B322: =IF(COUNTIF(C:C, A322) = 0, "no", IF(COUNTIF(C:C, A322) = 1, "OK", "duplicate")) -> OK | C322: https://github.com/jpmorganchase/salt-ds/pull/154#issuecomment-1148346047 | E322: =IF(COUNTIF(A:A, C322) = 0, "no", IF(COUNTIF(A:A, C322) = 1, "OK", "duplicate")) -> OK | G322: https://github.com/nodejs/nodejs.org/pull/7754#issuecomment-2888992525 | H322: =IF(COUNTIF(A:A, G322) = 0, "no", IF(COUNTIF(A:A, G322) = 1, "OK", "duplicate")) -> no | I322: {=_xludf.XLOOKUP(G322,Conflict!$A$2:$A$35,Conflict!$I$2:$I$35)} -> #NAME? | J322: {=_xludf.XLOOKUP(G322,Conflict!$A$2:$A$35,Conflict!$J$2:$J$35)} -> #NAME?
... A335: https://github.com/wellcomecollection/wellcomecollection.org/pull/8945#discussion_r1037122436 | B335: =IF(COUNTIF(C:C, A335) = 0, "no", IF(COUNTIF(C:C, A335) = 1, "OK", "duplicate")) -> OK | C335: https://github.com/coder/coder/pull/16020#issuecomment-2569139239 | E335: =IF(COUNTIF(A:A, C335) = 0, "no", IF(COUNTIF(A:A, C335) = 1, "OK", "duplicate")) -> OK | G335: https://github.com/Khan/perseus/pull/2728#discussion_r2226684249 | H335: =IF(COUNTIF(A:A, G335) = 0, "no", IF(COUNTIF(A:A, G335) = 1, "OK", "duplicate")) -> no | I335: {=_xludf.XLOOKUP(G335,Conflict!$A$2:$A$35,Conflict!$I$2:$I$35)} -> #NAME? | J335: {=_xludf.XLOOKUP(G335,Conflict!$A$2:$A$35,Conflict!$J$2:$J$35)} -> #NAME?
A336: https://github.com/DouyinFE/semi-design/pull/1317#issuecomment-1339101503 | B336: =IF(COUNTIF(C:C, A336) = 0, "no", IF(COUNTIF(C:C, A336) = 1, "OK", "duplicate")) -> OK | C336: ←これはURLが見えない | G336: https://github.com/recharts/recharts/pull/6059#issuecomment-3037435884 | H336: =IF(COUNTIF(A:A, G336) = 0, "no", IF(COUNTIF(A:A, G336) = 1, "OK", "duplicate")) -> no | I336: {=_xludf.XLOOKUP(G336,Conflict!$A$2:$A$35,Conflict!$I$2:$I$35)} -> #NAME? | J336: {=_xludf.XLOOKUP(G336,Conflict!$A$2:$A$35,Conflict!$J$2:$J$35)} -> #NAME?
A337: https://github.com/storybookjs/storybook/pull/20359#issuecomment-1361050002 | B337: =IF(COUNTIF(C:C, A337) = 0, "no", IF(COUNTIF(C:C, A337) = 1, "OK", "duplicate")) -> OK | C337: ←これはURLが見えない | G337: https://github.com/Khan/wonder-blocks/pull/2715#issuecomment-3104643517 | H337: =IF(COUNTIF(A:A, G337) = 0, "no", IF(COUNTIF(A:A, G337) = 1, "OK", "duplicate")) -> no | I337: {=_xludf.XLOOKUP(G337,Conflict!$A$2:$A$35,Conflict!$I$2:$I$35)} -> #NAME? | J337: {=_xludf.XLOOKUP(G337,Conflict!$A$2:$A$35,Conflict!$J$2:$J$35)} -> #NAME?
A338: https://github.com/ni/nimble/pull/927#discussion_r1050858002 | B338: =IF(COUNTIF(C:C, A338) = 0, "no", IF(COUNTIF(C:C, A338) = 1, "OK", "duplicate")) -> OK | C338: ←これはURLが見えない | G338: https://github.com/Khan/wonder-blocks/pull/2766#discussion_r2294739847 | H338: =IF(COUNTIF(A:A, G338) = 0, "no", IF(COUNTIF(A:A, G338) = 1, "OK", "duplicate")) -> no | I338: {=_xludf.XLOOKUP(G338,Conflict!$A$2:$A$35,Conflict!$I$2:$I$35)} -> #NAME? | J338: {=_xludf.XLOOKUP(G338,Conflict!$A$2:$A$35,Conflict!$J$2:$J$35)} -> #NAME?
A339: https://github.com/chanzuckerberg/edu-design-system/pull/1440#issuecomment-1357892871 | B339: =IF(COUNTIF(C:C, A339) = 0, "no", IF(COUNTIF(C:C, A339) = 1, "OK", "duplicate")) -> OK | C339: ←これはURLが見えない | G339: https://github.com/Khan/wonder-blocks/pull/2758#discussion_r2279534507 | H339: =IF(COUNTIF(A:A, G339) = 0, "no", IF(COUNTIF(A:A, G339) = 1, "OK", "duplicate")) -> no | I339: {=_xludf.XLOOKUP(G339,Conflict!$A$2:$A$35,Conflict!$I$2:$I$35)} -> #NAME? | J339: {=_xludf.XLOOKUP(G339,Conflict!$A$2:$A$35,Conflict!$J$2:$J$35)} -> #NAME?
A340: https://github.com/chanzuckerberg/edu-design-system/pull/1440#issuecomment-1358114979 | B340: =IF(COUNTIF(C:C, A340) = 0, "no", IF(COUNTIF(C:C, A340) = 1, "OK", "duplicate")) -> OK | C340: ←これはURLが見えない | G340: https://github.com/coder/coder/pull/19753#discussion_r2380229424 | H340: =IF(COUNTIF(A:A, G340) = 0, "no", IF(COUNTIF(A:A, G340) = 1, "OK", "duplicate")) -> no | I340: {=_xludf.XLOOKUP(G340,Conflict!$A$2:$A$35,Conflict!$I$2:$I$35)} -> #NAME? | J340: {=_xludf.XLOOKUP(G340,Conflict!$A$2:$A$35,Conflict!$J$2:$J$35)} -> #NAME?
G341: https://github.com/adobe/react-spectrum/pull/8893#issuecomment-3314117225 | H341: =IF(COUNTIF(A:A, G341) = 0, "no", IF(COUNTIF(A:A, G341) = 1, "OK", "duplicate")) -> no | I341: {=_xludf.XLOOKUP(G341,Conflict!$A$2:$A$35,Conflict!$I$2:$I$35)} -> #NAME? | J341: {=_xludf.XLOOKUP(G341,Conflict!$A$2:$A$35,Conflict!$J$2:$J$35)} -> #NAME?
G342: https://github.com/opengovsg/isomer/pull/1585#issuecomment-3274242189 | H342: =IF(COUNTIF(A:A, G342) = 0, "no", IF(COUNTIF(A:A, G342) = 1, "OK", "duplicate")) -> no | I342: {=_xludf.XLOOKUP(G342,Conflict!$A$2:$A$35,Conflict!$I$2:$I$35)} -> #NAME? | J342: {=_xludf.XLOOKUP(G342,Conflict!$A$2:$A$35,Conflict!$J$2:$J$35)} -> #NAME?
G343: https://github.com/Khan/wonder-blocks/pull/2786#discussion_r2349918819 | H343: =IF(COUNTIF(A:A, G343) = 0, "no", IF(COUNTIF(A:A, G343) = 1, "OK", "duplicate")) -> no | I343: {=_xludf.XLOOKUP(G343,Conflict!$A$2:$A$35,Conflict!$I$2:$I$35)} -> #NAME? | J343: {=_xludf.XLOOKUP(G343,Conflict!$A$2:$A$35,Conflict!$J$2:$J$35)} -> #NAME?
G344: https://github.com/Khan/wonder-blocks/pull/2786#discussion_r2353846205 | H344: =IF(COUNTIF(A:A, G344) = 0, "no", IF(COUNTIF(A:A, G344) = 1, "OK", "duplicate")) -> no | I344: {=_xludf.XLOOKUP(G344,Conflict!$A$2:$A$35,Conflict!$I$2:$I$35)} -> #NAME? | J344: {=_xludf.XLOOKUP(G344,Conflict!$A$2:$A$35,Conflict!$J$2:$J$35)} -> #NAME?
A345: これは前のやつのclosed以外を弾いたやつかも．．？みてopenは弾いていると思うけどclosedは入ってるかも

Sheet saner-vrt
A1: PR | B1: LABEL
A2: https://github.com/storybookjs/storybook/pull/20712#discussion_r1083565846 | B2: =IF(A2=Label!A2,Label!B2,"not yet") -> Focus Does Not Work
A3: https://github.com/storybookjs/storybook/pull/20712#discussion_r1083724374 | B3: =IF(A3=Label!A3,Label!B3,"not yet") -> OutOfScope: Duplicates
A4: https://github.com/ni/nimble/pull/966#discussion_r1074023214 | B4: =IF(A4=Label!A4,Label!B4,"not yet") -> Size of Page/Header Changed
A5: https://github.com/guardian/dotcom-rendering/pull/6954#issuecomment-1383873154 | B5: =IF(A5=Label!A5,Label!B5,"not yet") -> OutOfScope: Cannot access
A6: https://github.com/GCTC-NTGC/gc-digital-talent/pull/5740#issuecomment-1440357711 | B6: =IF(A6=Label!A6,Label!B6,"not yet") -> Text Size Changed
A7: https://github.com/storybookjs/storybook/pull/20995#issuecomment-1426807019 | B7: =IF(A7=Label!A7,Label!B7,"not yet") -> OutOfScope: Duplicates
A8: https://github.com/guardian/dotcom-rendering/pull/7128#issuecomment-1422355751 | B8: =IF(A8=Label!A8,Label!B8,"not yet") -> Layout Shifted
A9: https://github.com/guardian/dotcom-rendering/pull/7128#issuecomment-1422375286 | B9: =IF(A9=Label!A9,Label!B9,"not yet") -> OutOfScope: Duplicates
A10: https://github.com/guardian/dotcom-rendering/pull/7128#issuecomment-1422416345 | B10: =IF(A10=Label!A10,Label!B10,"not yet") -> OutOfScope: Duplicates
A11: https://github.com/ithaka/pharos/pull/503#discussion_r1146494323 | B11: =IF(A11=Label!A11,Label!B11,"not yet") -> Border Disappeared
A12: https://github.com/adobe/react-spectrum/pull/4243#issuecomment-1481577294 | B12: =IF(A12=Label!A12,Label!B12,"not yet") -> OutOfScope: New Story
A13: https://github.com/NeurodataWithoutBorders/nwb-guide/pull/74#issuecomment-1486132202 | B13: =IF(A13=Label!A13,Label!B13,"not yet") -> Image Replaced
... A309: https://github.com/chanzuckerberg/edu-design-system/pull/1440#issuecomment-1358114979 | B309: =IF(A309=Label!A309,Label!B309,"not yet") -> OutOfScope: Duplicates
A310: https://github.com/serendie/serendie/pull/28#issuecomment-2670908811 | B310: =IF(A310=#REF!,#REF!,"no") -> #REF! | C310: =IF(A310=#REF!,#REF!,"no") -> #REF!
A311: https://github.com/opengovsg/isomer/pull/1144#discussion_r1974730734 | B311: =IF(A311=Conflict!A2,Conflict!I2,"no") -> OutOfScope: Not VRT Discussion | C311: =IF(A311=Conflict!A2,Conflict!J2,"no") -> 0
A312: https://github.com/department-of-veterans-affairs/component-library/pull/1487#issuecomment-2668874799 | B312: =IF(A312=#REF!,#REF!,"no") -> #REF! | C312: =IF(A312=#REF!,#REF!,"no") -> #REF!
A313: https://github.com/Esri/calcite-design-system/pull/11759#issuecomment-2738116384 | B313: =IF(A313=Conflict!A3,Conflict!I3,"no") -> OutOfScope: Duplicates | C313: =IF(A313=Conflict!A3,Conflict!J3,"no") -> 0
A314: https://github.com/openops-cloud/openops/pull/286#issuecomment-2750462330 | B314: =IF(A314=Conflict!A4,Conflict!I4,"no") -> OutOfScope: Duplicates | C314: =IF(A314=Conflict!A4,Conflict!J4,"no") -> 0
A315: https://github.com/temporalio/ui/pull/2599#issuecomment-2730449028 | B315: =IF(A315=Conflict!A5,Conflict!I5,"no") -> Box Size Changed | C315: =IF(A315=Conflict!A5,Conflict!J5,"no") -> 0
A316: https://github.com/Khan/wonder-blocks/pull/2508#discussion_r2006483914 | B316: =IF(A316=Conflict!A6,Conflict!I6,"no") -> OutOfScope: New Story | C316: =IF(A316=Conflict!A6,Conflict!J6,"no") -> 0
A317: https://github.com/Khan/wonder-blocks/pull/2508#discussion_r2008301713 | B317: =IF(A317=Conflict!A7,Conflict!I7,"no") -> OutOfScope: New Story | C317: =IF(A317=Conflict!A7,Conflict!J7,"no") -> 0
A318: https://github.com/ory/elements/pull/371#discussion_r1977424201 | B318: =IF(A318=Conflict!A8,Conflict!I8,"no") -> Contents of Text Changed | C318: =IF(A318=Conflict!A8,Conflict!J8,"no") -> 0
A319: https://github.com/nl-design-system/denhaag/pull/1709#issuecomment-2703653274 | B319: =IF(A319=Conflict!A9,Conflict!I9,"no") -> No or Few Visual Diffrences Detected | C319: =IF(A319=Conflict!A9,Conflict!J9,"no") -> 0
A320: https://github.com/adobe/spectrum-css/pull/3593#issuecomment-2693948041 | B320: =IF(A320=Conflict!A10,Conflict!I10,"no") -> Border Color Changed | C320: =IF(A320=Conflict!A10,Conflict!J10,"no") -> 0
A321: https://github.com/nodejs/nodejs.org/pull/7638#issuecomment-2795597092 | B321: =IF(A321=Conflict!A11,Conflict!I11,"no") -> OutOfScope: New Story | C321: =IF(A321=Conflict!A11,Conflict!J11,"no") -> 0
A322: https://github.com/Khan/wonder-blocks/pull/2563#discussion_r2049478574 | B322: =IF(A322=Conflict!A12,Conflict!I12,"no") -> New Contents | C322: =IF(A322=Conflict!A12,Conflict!J12,"no") -> Box Color Changed
A323: https://github.com/nodejs/nodejs.org/pull/7754#issuecomment-2888992525 | B323: =IF(A323=Conflict!A13,Conflict!I13,"no") -> Layout Shifted | C323: =IF(A323=Conflict!A13,Conflict!J13,"no") -> 0
A324: https://github.com/nodejs/nodejs.org/pull/7754#issuecomment-2889053424 | B324: =IF(A324=Conflict!A14,Conflict!I14,"no") -> OutOfScope: Duplicates | C324: =IF(A324=Conflict!A14,Conflict!J14,"no") -> 0
... A345: https://github.com/Khan/wonder-blocks/pull/2786#discussion_r2353846205 | B345: =IF(A345=Conflict!A35,Conflict!I35,"no") -> OutOfScope: New Story | C345: =IF(A345=Conflict!A35,Conflict!J35,"no") -> 0

Sheet Horikawa
A1: PR_URL | C1: LABEL | D1: memo
A2: https://github.com/serendie/serendie/pull/28#issuecomment-2670908811 | B2: OutOfScope: New Story | D2: Menuタイトルのdropdownが開かない
A3: https://github.com/opengovsg/isomer/pull/1144#discussion_r1974730734 | B3: OutOfScope: Not VRT Discussion | D3: StorybookでCSSの色を上書きしたいのに、サイト本体の設定が読み込まれてしまい、意図した色にならない
A4: https://github.com/department-of-veterans-affairs/component-library/pull/1487#issuecomment-2668874799 | B4: Layout Shifted | D4: checkboxの空白が増えてる
A5: https://github.com/Esri/calcite-design-system/pull/11759#issuecomment-2738116384 | B5: OutOfScope: Duplicates | D5: コード変更が，余白にも影響してる
A6: https://github.com/openops-cloud/openops/pull/286#issuecomment-2750462330 | B6: OutOfScope: Duplicates | D6: ストーリーブックがreadOnlyになったので変更依頼を出してる
A7: https://github.com/temporalio/ui/pull/2599#issuecomment-2730449028 | C7: Box Size Changed
A8: https://github.com/Khan/wonder-blocks/pull/2508#discussion_r2006483914 | B8: OutOfScope: New Story | D8: 画像が勝手にトリミングされてる
A9: https://github.com/Khan/wonder-blocks/pull/2508#discussion_r2008301713 | B9: OutOfScope: New Story | D9: Chromatic側のスナップショット生成の問題
A10: https://github.com/ory/elements/pull/371#discussion_r1977424201 | C10: Contents of Text Changed
A11: https://github.com/nl-design-system/denhaag/pull/1709#issuecomment-2703653274 | C11: Specific Items are Mis-aligned | D11: 一部のアイテムがずれてる
A12: https://github.com/adobe/spectrum-css/pull/3593#issuecomment-2693948041 | B12: Border Color Changed
A13: https://github.com/nodejs/nodejs.org/pull/7638#issuecomment-2795597092 | B13: OutOfScope: New Story | D13: CHromaticが開かない
A14: https://github.com/Khan/wonder-blocks/pull/2563#discussion_r2049478574 | B14: Box Color Changed | C14: New Buttons
A15: https://github.com/nodejs/nodejs.org/pull/7754#issuecomment-2888992525 | B15: Layout Shifted
A16: https://github.com/nodejs/nodejs.org/pull/7754#issuecomment-2889053424 | B16: OutOfScope: Duplicates | D16: 上と同じやつ？
A17: https://github.com/nodejs/nodejs.org/pull/7754#issuecomment-2889218109 | B17: Layout Shifted | D17: 上と同じやつ？
A18: https://github.com/coder/coder/pull/17822#issuecomment-2884484097 | B18: Layout Shifted
A19: https://github.com/storacha/bluesky-backup-webapp-server/pull/171#discussion_r2096028845 | B19: OutOfScope: New Story
A20: https://github.com/Khan/wonder-blocks/pull/2602#discussion_r2098766914 | B20: OutOfScope: New Story | D20: テストを増やすべきっていうコメント，リンクに問題はなさそう
A21: https://github.com/Khan/wonder-blocks/pull/2602#discussion_r2103548556 | B21: OutOfScope: New Story | D21: テキストのフォントを確認するだけ，リグレッションを検出してるわけではなさそう
A22: https://github.com/Khan/wonder-blocks/pull/2600#issuecomment-2887722760 | B22: OutOfScope: New Story | D22: chromaticのバグ？
A23: https://github.com/recharts/recharts/pull/6008#issuecomment-3004356312 | B23: OutOfScope: Chromatic Error | D23: PRのコメント参照
A24: https://github.com/Khan/wonder-blocks/pull/2661#discussion_r2150341785 | B24: OutOfScope: New Story | C24: Box Shape Changed
A25: https://github.com/coder/coder/pull/18445#discussion_r2157012512 | B25: Undefined/Wrong State is Shown | D25: Label still shows preset 1 but the value in the form is that of preset 2.
A26: https://github.com/Esri/calcite-design-system/pull/12595#issuecomment-3134461611 | B26: Layout Shifted
A27: https://github.com/kiva/kv-ui-elements/pull/597#issuecomment-3050388713 | B27: OutOfScope: Not VRT Discussion | D27: コレはchromaticとかフロントエンドの問題というよりは，シナリオを修正すべきだと提案してるだけ
A28: https://github.com/Khan/perseus/pull/2728#discussion_r2226684249 | B28: OutOfScope: New Story | D28: コレはchromaticとかフロントエンドの問題というよりは，シナリオを消すべきだと提案してるだけ
A29: https://github.com/recharts/recharts/pull/6059#issuecomment-3037435884 | B29: New Contents | C29: Layout Shifted | D29: スナップショットの変更
A30: https://github.com/Khan/wonder-blocks/pull/2715#issuecomment-3104643517 | B30: Layout Shifted | D30: リグレッションの問題ではなく，アクセシビリティ改善の議論をしてる
A31: https://github.com/Khan/wonder-blocks/pull/2766#discussion_r2294739847 | B31: Box Color Changed
A32: https://github.com/Khan/wonder-blocks/pull/2758#discussion_r2279534507 | B32: Border Color Changed
A33: https://github.com/coder/coder/pull/19753#discussion_r2380229424 | B33: OutOfScope: Chromatic Error
A34: https://github.com/adobe/react-spectrum/pull/8893#issuecomment-3314117225 | B34: Layout Shifted
A35: https://github.com/opengovsg/isomer/pull/1585#issuecomment-3274242189 | B35: OutOfScope: Duplicates
A36: https://github.com/Khan/wonder-blocks/pull/2786#discussion_r2349918819 | B36: OutOfScope: New Story | D36: 現在のスナップショットがテストの目的を果たしていない
A37: https://github.com/Khan/wonder-blocks/pull/2786#discussion_r2353846205 | B37: OutOfScope: New Story | D37: 差分がない気がする

Sheet MIku
A1: PR_URL | B1: LABEL | C1: LABEL | D1: memo
A2: https://github.com/serendie/serendie/pull/28#issuecomment-2670908811 | B2: OutOfScope: New Story
A3: https://github.com/opengovsg/isomer/pull/1144#discussion_r1974730734 | B3: OutOfScope: Not VRT Discussion
A4: https://github.com/department-of-veterans-affairs/component-library/pull/1487#issuecomment-2668874799 | B4: Layout Shifted
A5: https://github.com/Esri/calcite-design-system/pull/11759#issuecomment-2738116384 | B5: OutOfScope: Duplicates
A6: https://github.com/openops-cloud/openops/pull/286#issuecomment-2750462330 | B6: OutOfScope: Duplicates
A7: https://github.com/temporalio/ui/pull/2599#issuecomment-2730449028 | B7: Box Shape Changed
A8: https://github.com/Khan/wonder-blocks/pull/2508#discussion_r2006483914 | B8: OutOfScope: New Story
A9: https://github.com/Khan/wonder-blocks/pull/2508#discussion_r2008301713 | B9: OutOfScope: New Story
A10: https://github.com/ory/elements/pull/371#discussion_r1977424201 | B10: Contents of Text Changed
A11: https://github.com/nl-design-system/denhaag/pull/1709#issuecomment-2703653274 | B11: Layout Changed
A12: https://github.com/adobe/spectrum-css/pull/3593#issuecomment-2693948041 | B12: Border Color Changed
A13: https://github.com/nodejs/nodejs.org/pull/7638#issuecomment-2795597092 | B13: OutOfScope: New Story
A14: https://github.com/Khan/wonder-blocks/pull/2563#discussion_r2049478574 | B14: New Contents | C14: Box Color Changed
A15: https://github.com/nodejs/nodejs.org/pull/7754#issuecomment-2888992525 | B15: Layout Shifted
A16: https://github.com/nodejs/nodejs.org/pull/7754#issuecomment-2889053424 | B16: OutOfScope: Duplicates
A17: https://github.com/nodejs/nodejs.org/pull/7754#issuecomment-2889218109 | B17: Layout Shifted
A18: https://github.com/coder/coder/pull/17822#issuecomment-2884484097 | B18: Layout Shifted
A19: https://github.com/storacha/bluesky-backup-webapp-server/pull/171#discussion_r2096028845 | B19: OutOfScope: New Story
A20: https://github.com/Khan/wonder-blocks/pull/2602#discussion_r2098766914 | B20: OutOfScope: New Story
A21: https://github.com/Khan/wonder-blocks/pull/2602#discussion_r2103548556 | B21: OutOfScope: New Story
A22: https://github.com/Khan/wonder-blocks/pull/2600#issuecomment-2887722760 | B22: OutOfScope: New Story
A23: https://github.com/recharts/recharts/pull/6008#issuecomment-3004356312 | B23: Text Disappeared
A24: https://github.com/Khan/wonder-blocks/pull/2661#discussion_r2150341785 | B24: OutOfScope: New Story
A25: https://github.com/coder/coder/pull/18445#discussion_r2157012512 | B25: Undefined/Wrong State is Shown | D25: Labelの設定を変更したため起こったVRT
A26: https://github.com/Esri/calcite-design-system/pull/12595#issuecomment-3134461611 | B26: Layout Shifted
A27: https://github.com/kiva/kv-ui-elements/pull/597#issuecomment-3050388713 | B27: OutOfScope: Not VRT Discussion
A28: https://github.com/Khan/perseus/pull/2728#discussion_r2226684249 | B28: OutOfScope: New Story
A29: https://github.com/recharts/recharts/pull/6059#issuecomment-3037435884 | B29: Layout Shifted | C29: New Contents
A30: https://github.com/Khan/wonder-blocks/pull/2715#issuecomment-3104643517 | B30: Layout Shifted
A31: https://github.com/Khan/wonder-blocks/pull/2766#discussion_r2294739847 | B31: Box Color Changed
A32: https://github.com/Khan/wonder-blocks/pull/2758#discussion_r2279534507 | B32: Border Color Changed
A33: https://github.com/coder/coder/pull/19753#discussion_r2380229424 | B33: OutOfScope: Chromatic Error
A34: https://github.com/adobe/react-spectrum/pull/8893#issuecomment-3314117225 | B34: New Contents
A35: https://github.com/opengovsg/isomer/pull/1585#issuecomment-3274242189 | B35: Layout Shifted
A36: https://github.com/Khan/wonder-blocks/pull/2786#discussion_r2349918819 | B36: OutOfScope: New Story
A37: https://github.com/Khan/wonder-blocks/pull/2786#discussion_r2353846205 | B37: OutOfScope: New Story

Sheet Detecton Number
A1: Detection | C1: Category
A2: Layout Shifted | B2: 42 | C2: Layout | D2: 75
A3: Layout Changed | B3: 12 | C3: Appearance | D3: 52
A4: Size of Page/Header Changed | B4: 11 | C4: Color | D4: 28
A5: Specific Items are Mis-aligned | B5: 10 | C5: Text | D5: 18
A6: Box Size Changed | B6: 18 | C6: State | D6: 13
A7: New Contents | B7: 10 | C7: Test | D7: 12
A8: Contents Disappeared | B8: 6 | C8: Image | D8: 8
A9: Box Shape Changed | B9: 6
A10: Box Disappeared | B10: 4 | C10: Valid Total | D10: 206
A11: Border Disappeared | B11: 3 | C11: Invalid Total | D11: 155
A12: Wrong Border Thickness | B12: 2 | C12: Total | D12: 361
A13: New Buttons | B13: 2
A14: New Border Appeared | B14: 1
A15: Box Color Changed | B15: 16
A16: Text Color Changed | B16: 8
A17: Border Color Changed | B17: 4
A18: Text Disappeared | B18: 7
A19: Contents of Text Changed | B19: 5
A20: Text Size Changed | B20: 3
A21: New Text | B21: 3
A22: Undefined/Wrong State is Shown | B22: 8
A23: Default State is Changed | B23: 5
A24: No or Few Visual Diffrences Detected | B24: 5
... A42: error | B42: 10

Sheet Conflict
A1: PR_URL | B1: LABEL(MIKU) | C1: LABEL(MIKU) | D1: LABEL (Horikawa) | E1: LABEL (Horikawa) | F1: Conflict or no | G1: LABEL(Kashiwa) | H1: LABEL(Kashiwa) | I1: FINAL | J1: FINAL | K1: 一致率
A2: https://github.com/opengovsg/isomer/pull/1144#discussion_r1974730734 | B2: OutOfScope: Not VRT Discussion | D2: OutOfScope: Not VRT Discussion | F2: =IF(OR(AND(B2=D2, C2=E2), AND(B2=E2, C2=D2)), "ok", "conflict") -> ok | I2: =IF(F2="ok",B2,G2) -> OutOfScope: Not VRT Discussion | J2: =IF(F2="ok",C2,H2) -> 0 | K2: =COUNTIF(D2:E2, B2) + IF(AND(C2<>"", C2<>B2), COUNTIF(D2:E2, C2), 0) -> 1 | L2: =IF(B2<>"", IF(COUNTIF(D2:E2, B2)=0, 1, 0), 0) + IF(AND(C2<>"", C2<>B2), IF(COUNTIF(D2:E2, C2)=0, 1, 0), 0) + IF(D2<>"", IF(COUNTIF(B2:C2, D2)=0, 1, 0), 0) + IF(AND(E2<>"", E2<>D2), IF(COUNTIF(B2:C2, E2)=0, 1, 0), 0) -> 0
A3: https://github.com/Esri/calcite-design-system/pull/11759#issuecomment-2738116384 | B3: OutOfScope: Duplicates | D3: OutOfScope: Duplicates | F3: =IF(OR(AND(B3=D3, C3=E3), AND(B3=E3, C3=D3)), "ok", "conflict") -> ok | I3: =IF(F3="ok",B3,G3) -> OutOfScope: Duplicates | J3: =IF(F3="ok",C3,H3) -> 0 | K3: =COUNTIF(D3:E3, B3) + IF(AND(C3<>"", C3<>B3), COUNTIF(D3:E3, C3), 0) -> 1 | L3: =IF(B3<>"", IF(COUNTIF(D3:E3, B3)=0, 1, 0), 0) + IF(AND(C3<>"", C3<>B3), IF(COUNTIF(D3:E3, C3)=0, 1, 0), 0) + IF(D3<>"", IF(COUNTIF(B3:C3, D3)=0, 1, 0), 0) + IF(AND(E3<>"", E3<>D3), IF(COUNTIF(B3:C3, E3)=0, 1, 0), 0) -> 0
A4: https://github.com/openops-cloud/openops/pull/286#issuecomment-2750462330 | B4: OutOfScope: Duplicates | D4: OutOfScope: Duplicates | F4: =IF(OR(AND(B4=D4, C4=E4), AND(B4=E4, C4=D4)), "ok", "conflict") -> ok | I4: =IF(F4="ok",B4,G4) -> OutOfScope: Duplicates | J4: =IF(F4="ok",C4,H4) -> 0 | K4: =COUNTIF(D4:E4, B4) + IF(AND(C4<>"", C4<>B4), COUNTIF(D4:E4, C4), 0) -> 1 | L4: =IF(B4<>"", IF(COUNTIF(D4:E4, B4)=0, 1, 0), 0) + IF(AND(C4<>"", C4<>B4), IF(COUNTIF(D4:E4, C4)=0, 1, 0), 0) + IF(D4<>"", IF(COUNTIF(B4:C4, D4)=0, 1, 0), 0) + IF(AND(E4<>"", E4<>D4), IF(COUNTIF(B4:C4, E4)=0, 1, 0), 0) -> 0
A5: https://github.com/temporalio/ui/pull/2599#issuecomment-2730449028 | B5: Box Shape Changed | D5: Box Size Changed | F5: =IF(OR(AND(B5=D5, C5=E5), AND(B5=E5, C5=D5)), "ok", "conflict") -> conflict | G5: Box Size Changed | I5: =IF(F5="ok",B5,G5) -> Box Size Changed | J5: =IF(F5="ok",C5,H5) -> 0 | K5: =COUNTIF(D5:E5, B5) + IF(AND(C5<>"", C5<>B5), COUNTIF(D5:E5, C5), 0) -> 0 | L5: =IF(B5<>"", IF(COUNTIF(D5:E5, B5)=0, 1, 0), 0) + IF(AND(C5<>"", C5<>B5), IF(COUNTIF(D5:E5, C5)=0, 1, 0), 0) + IF(D5<>"", IF(COUNTIF(B5:C5, D5)=0, 1, 0), 0) + IF(AND(E5<>"", E5<>D5), IF(COUNTIF(B5:C5, E5)=0, 1, 0), 0) -> 2
A6: https://github.com/Khan/wonder-blocks/pull/2508#discussion_r2006483914 | B6: OutOfScope: New Story | D6: OutOfScope: New Story | F6: =IF(OR(AND(B6=D6, C6=E6), AND(B6=E6, C6=D6)), "ok", "conflict") -> ok | I6: =IF(F6="ok",B6,G6) -> OutOfScope: New Story | J6: =IF(F6="ok",C6,H6) -> 0 | K6: =COUNTIF(D6:E6, B6) + IF(AND(C6<>"", C6<>B6), COUNTIF(D6:E6, C6), 0) -> 1 | L6: =IF(B6<>"", IF(COUNTIF(D6:E6, B6)=0, 1, 0), 0) + IF(AND(C6<>"", C6<>B6), IF(COUNTIF(D6:E6, C6)=0, 1, 0), 0) + IF(D6<>"", IF(COUNTIF(B6:C6, D6)=0, 1, 0), 0) + IF(AND(E6<>"", E6<>D6), IF(COUNTIF(B6:C6, E6)=0, 1, 0), 0) -> 0
A7: https://github.com/Khan/wonder-blocks/pull/2508#discussion_r2008301713 | B7: OutOfScope: New Story | D7: OutOfScope: New Story | F7: =IF(OR(AND(B7=D7, C7=E7), AND(B7=E7, C7=D7)), "ok", "conflict") -> ok | I7: =IF(F7="ok",B7,G7) -> OutOfScope: New Story | J7: =IF(F7="ok",C7,H7) -> 0 | K7: =COUNTIF(D7:E7, B7) + IF(AND(C7<>"", C7<>B7), COUNTIF(D7:E7, C7), 0) -> 1 | L7: =IF(B7<>"", IF(COUNTIF(D7:E7, B7)=0, 1, 0), 0) + IF(AND(C7<>"", C7<>B7), IF(COUNTIF(D7:E7, C7)=0, 1, 0), 0) + IF(D7<>"", IF(COUNTIF(B7:C7, D7)=0, 1, 0), 0) + IF(AND(E7<>"", E7<>D7), IF(COUNTIF(B7:C7, E7)=0, 1, 0), 0) -> 0
A8: https://github.com/ory/elements/pull/371#discussion_r1977424201 | B8: Contents of Text Changed | D8: Contents of Text Changed | F8: =IF(OR(AND(B8=D8, C8=E8), AND(B8=E8, C8=D8)), "ok", "conflict") -> ok | I8: =IF(F8="ok",B8,G8) -> Contents of Text Changed | J8: =IF(F8="ok",C8,H8) -> 0 | K8: =COUNTIF(D8:E8, B8) + IF(AND(C8<>"", C8<>B8), COUNTIF(D8:E8, C8), 0) -> 1 | L8: =IF(B8<>"", IF(COUNTIF(D8:E8, B8)=0, 1, 0), 0) + IF(AND(C8<>"", C8<>B8), IF(COUNTIF(D8:E8, C8)=0, 1, 0), 0) + IF(D8<>"", IF(COUNTIF(B8:C8, D8)=0, 1, 0), 0) + IF(AND(E8<>"", E8<>D8), IF(COUNTIF(B8:C8, E8)=0, 1, 0), 0) -> 0
A9: https://github.com/nl-design-system/denhaag/pull/1709#issuecomment-2703653274 | B9: Layout Changed | D9: Specific Items are Mis-aligned | F9: =IF(OR(AND(B9=D9, C9=E9), AND(B9=E9, C9=D9)), "ok", "conflict") -> conflict | G9: No or Few Visual Diffrences Detected | I9: =IF(F9="ok",B9,G9) -> No or Few Visual Diffrences Detected | J9: =IF(F9="ok",C9,H9) -> 0 | K9: =COUNTIF(D9:E9, B9) + IF(AND(C9<>"", C9<>B9), COUNTIF(D9:E9, C9), 0) -> 0 | L9: =IF(B9<>"", IF(COUNTIF(D9:E9, B9)=0, 1, 0), 0) + IF(AND(C9<>"", C9<>B9), IF(COUNTIF(D9:E9, C9)=0, 1, 0), 0) + IF(D9<>"", IF(COUNTIF(B9:C9, D9)=0, 1, 0), 0) + IF(AND(E9<>"", E9<>D9), IF(COUNTIF(B9:C9, E9)=0, 1, 0), 0) -> 2
A10: https://github.com/adobe/spectrum-css/pull/3593#issuecomment-2693948041 | B10: Border Color Changed | D10: Border Color Changed | F10: =IF(OR(AND(B10=D10, C10=E10), AND(B10=E10, C10=D10)), "ok", "conflict") -> ok | I10: =IF(F10="ok",B10,G10) -> Border Color Changed | J10: =IF(F10="ok",C10,H10) -> 0 | K10: =COUNTIF(D10:E10, B10) + IF(AND(C10<>"", C10<>B10), COUNTIF(D10:E10, C10), 0) -> 1 | L10: =IF(B10<>"", IF(COUNTIF(D10:E10, B10)=0, 1, 0), 0) + IF(AND(C10<>"", C10<>B10), IF(COUNTIF(D10:E10, C10)=0, 1, 0), 0) + IF(D10<>"", IF(COUNTIF(B10:C10, D10)=0, 1, 0), 0) + IF(AND(E10<>"", E10<>D10), IF(COUNTIF(B10:C10, E10)=0, 1, 0), 0) -> 0
A11: https://github.com/nodejs/nodejs.org/pull/7638#issuecomment-2795597092 | B11: OutOfScope: New Story | D11: OutOfScope: New Story | F11: =IF(OR(AND(B11=D11, C11=E11), AND(B11=E11, C11=D11)), "ok", "conflict") -> ok | I11: =IF(F11="ok",B11,G11) -> OutOfScope: New Story | J11: =IF(F11="ok",C11,H11) -> 0 | K11: =COUNTIF(D11:E11, B11) + IF(AND(C11<>"", C11<>B11), COUNTIF(D11:E11, C11), 0) -> 1 | L11: =IF(B11<>"", IF(COUNTIF(D11:E11, B11)=0, 1, 0), 0) + IF(AND(C11<>"", C11<>B11), IF(COUNTIF(D11:E11, C11)=0, 1, 0), 0) + IF(D11<>"", IF(COUNTIF(B11:C11, D11)=0, 1, 0), 0) + IF(AND(E11<>"", E11<>D11), IF(COUNTIF(B11:C11, E11)=0, 1, 0), 0) -> 0
A12: https://github.com/Khan/wonder-blocks/pull/2563#discussion_r2049478574 | B12: New Contents | C12: Box Color Changed | D12: Box Color Changed | E12: New Buttons | F12: =IF(OR(AND(B12=D12, C12=E12), AND(B12=E12, C12=D12)), "ok", "conflict") -> conflict | G12: New Contents | H12: Box Color Changed | I12: =IF(F12="ok",B12,G12) -> New Contents | J12: =IF(F12="ok",C12,H12) -> Box Color Changed | K12: =COUNTIF(D12:E12, B12) + IF(AND(C12<>"", C12<>B12), COUNTIF(D12:E12, C12), 0) -> 1 | L12: =IF(B12<>"", IF(COUNTIF(D12:E12, B12)=0, 1, 0), 0) + IF(AND(C12<>"", C12<>B12), IF(COUNTIF(D12:E12, C12)=0, 1, 0), 0) + IF(D12<>"", IF(COUNTIF(B12:C12, D12)=0, 1, 0), 0) + IF(AND(E12<>"", E12<>D12), IF(COUNTIF(B12:C12, E12)=0, 1, 0), 0) -> 2
A13: https://github.com/nodejs/nodejs.org/pull/7754#issuecomment-2888992525 | B13: Layout Shifted | D13: Layout Shifted | F13: =IF(OR(AND(B13=D13, C13=E13), AND(B13=E13, C13=D13)), "ok", "conflict") -> ok | I13: =IF(F13="ok",B13,G13) -> Layout Shifted | J13: =IF(F13="ok",C13,H13) -> 0 | K13: =COUNTIF(D13:E13, B13) + IF(AND(C13<>"", C13<>B13), COUNTIF(D13:E13, C13), 0) -> 1 | L13: =IF(B13<>"", IF(COUNTIF(D13:E13, B13)=0, 1, 0), 0) + IF(AND(C13<>"", C13<>B13), IF(COUNTIF(D13:E13, C13)=0, 1, 0), 0) + IF(D13<>"", IF(COUNTIF(B13:C13, D13)=0, 1, 0), 0) + IF(AND(E13<>"", E13<>D13), IF(COUNTIF(B13:C13, E13)=0, 1, 0), 0) -> 0
A14: https://github.com/nodejs/nodejs.org/pull/7754#issuecomment-2889053424 | B14: OutOfScope: Duplicates | D14: OutOfScope: Duplicates | F14: =IF(OR(AND(B14=D14, C14=E14), AND(B14=E14, C14=D14)), "ok", "conflict") -> ok | I14: =IF(F14="ok",B14,G14) -> OutOfScope: Duplicates | J14: =IF(F14="ok",C14,H14) -> 0 | K14: =COUNTIF(D14:E14, B14) + IF(AND(C14<>"", C14<>B14), COUNTIF(D14:E14, C14), 0) -> 1 | L14: =IF(B14<>"", IF(COUNTIF(D14:E14, B14)=0, 1, 0), 0) + IF(AND(C14<>"", C14<>B14), IF(COUNTIF(D14:E14, C14)=0, 1, 0), 0) + IF(D14<>"", IF(COUNTIF(B14:C14, D14)=0, 1, 0), 0) + IF(AND(E14<>"", E14<>D14), IF(COUNTIF(B14:C14, E14)=0, 1, 0), 0) -> 0
A15: https://github.com/nodejs/nodejs.org/pull/7754#issuecomment-2889218109 | B15: Layout Shifted | D15: Layout Shifted | F15: =IF(OR(AND(B15=D15, C15=E15), AND(B15=E15, C15=D15)), "ok", "conflict") -> ok | I15: =IF(F15="ok",B15,G15) -> Layout Shifted | J15: =IF(F15="ok",C15,H15) -> 0 | K15: =COUNTIF(D15:E15, B15) + IF(AND(C15<>"", C15<>B15), COUNTIF(D15:E15, C15), 0) -> 1 | L15: =IF(B15<>"", IF(COUNTIF(D15:E15, B15)=0, 1, 0), 0) + IF(AND(C15<>"", C15<>B15), IF(COUNTIF(D15:E15, C15)=0, 1, 0), 0) + IF(D15<>"", IF(COUNTIF(B15:C15, D15)=0, 1, 0), 0) + IF(AND(E15<>"", E15<>D15), IF(COUNTIF(B15:C15, E15)=0, 1, 0), 0) -> 0
A16: https://github.com/coder/coder/pull/17822#issuecomment-2884484097 | B16: Layout Shifted | D16: Layout Shifted | F16: =IF(OR(AND(B16=D16, C16=E16), AND(B16=E16, C16=D16)), "ok", "conflict") -> ok | I16: =IF(F16="ok",B16,G16) -> Layout Shifted | J16: =IF(F16="ok",C16,H16) -> 0 | K16: =COUNTIF(D16:E16, B16) + IF(AND(C16<>"", C16<>B16), COUNTIF(D16:E16, C16), 0) -> 1 | L16: =IF(B16<>"", IF(COUNTIF(D16:E16, B16)=0, 1, 0), 0) + IF(AND(C16<>"", C16<>B16), IF(COUNTIF(D16:E16, C16)=0, 1, 0), 0) + IF(D16<>"", IF(COUNTIF(B16:C16, D16)=0, 1, 0), 0) + IF(AND(E16<>"", E16<>D16), IF(COUNTIF(B16:C16, E16)=0, 1, 0), 0) -> 0
A17: https://github.com/storacha/bluesky-backup-webapp-server/pull/171#discussion_r2096028845 | B17: OutOfScope: New Story | D17: OutOfScope: New Story | F17: =IF(OR(AND(B17=D17, C17=E17), AND(B17=E17, C17=D17)), "ok", "conflict") -> ok | I17: =IF(F17="ok",B17,G17) -> OutOfScope: New Story | J17: =IF(F17="ok",C17,H17) -> 0 | K17: =COUNTIF(D17:E17, B17) + IF(AND(C17<>"", C17<>B17), COUNTIF(D17:E17, C17), 0) -> 1 | L17: =IF(B17<>"", IF(COUNTIF(D17:E17, B17)=0, 1, 0), 0) + IF(AND(C17<>"", C17<>B17), IF(COUNTIF(D17:E17, C17)=0, 1, 0), 0) + IF(D17<>"", IF(COUNTIF(B17:C17, D17)=0, 1, 0), 0) + IF(AND(E17<>"", E17<>D17), IF(COUNTIF(B17:C17, E17)=0, 1, 0), 0) -> 0
A18: https://github.com/Khan/wonder-blocks/pull/2602#discussion_r2098766914 | B18: OutOfScope: New Story | D18: OutOfScope: New Story | F18: =IF(OR(AND(B18=D18, C18=E18), AND(B18=E18, C18=D18)), "ok", "conflict") -> ok | I18: =IF(F18="ok",B18,G18) -> OutOfScope: New Story | J18: =IF(F18="ok",C18,H18) -> 0 | K18: =COUNTIF(D18:E18, B18) + IF(AND(C18<>"", C18<>B18), COUNTIF(D18:E18, C18), 0) -> 1 | L18: =IF(B18<>"", IF(COUNTIF(D18:E18, B18)=0, 1, 0), 0) + IF(AND(C18<>"", C18<>B18), IF(COUNTIF(D18:E18, C18)=0, 1, 0), 0) + IF(D18<>"", IF(COUNTIF(B18:C18, D18)=0, 1, 0), 0) + IF(AND(E18<>"", E18<>D18), IF(COUNTIF(B18:C18, E18)=0, 1, 0), 0) -> 0
A19: https://github.com/Khan/wonder-blocks/pull/2602#discussion_r2103548556 | B19: OutOfScope: New Story | D19: OutOfScope: New Story | F19: =IF(OR(AND(B19=D19, C19=E19), AND(B19=E19, C19=D19)), "ok", "conflict") -> ok | I19: =IF(F19="ok",B19,G19) -> OutOfScope: New Story | J19: =IF(F19="ok",C19,H19) -> 0 | K19: =COUNTIF(D19:E19, B19) + IF(AND(C19<>"", C19<>B19), COUNTIF(D19:E19, C19), 0) -> 1 | L19: =IF(B19<>"", IF(COUNTIF(D19:E19, B19)=0, 1, 0), 0) + IF(AND(C19<>"", C19<>B19), IF(COUNTIF(D19:E19, C19)=0, 1, 0), 0) + IF(D19<>"", IF(COUNTIF(B19:C19, D19)=0, 1, 0), 0) + IF(AND(E19<>"", E19<>D19), IF(COUNTIF(B19:C19, E19)=0, 1, 0), 0) -> 0
A20: https://github.com/Khan/wonder-blocks/pull/2600#issuecomment-2887722760 | B20: OutOfScope: New Story | D20: OutOfScope: New Story | F20: =IF(OR(AND(B20=D20, C20=E20), AND(B20=E20, C20=D20)), "ok", "conflict") -> ok | I20: =IF(F20="ok",B20,G20) -> OutOfScope: New Story | J20: =IF(F20="ok",C20,H20) -> 0 | K20: =COUNTIF(D20:E20, B20) + IF(AND(C20<>"", C20<>B20), COUNTIF(D20:E20, C20), 0) -> 1 | L20: =IF(B20<>"", IF(COUNTIF(D20:E20, B20)=0, 1, 0), 0) + IF(AND(C20<>"", C20<>B20), IF(COUNTIF(D20:E20, C20)=0, 1, 0), 0) + IF(D20<>"", IF(COUNTIF(B20:C20, D20)=0, 1, 0), 0) + IF(AND(E20<>"", E20<>D20), IF(COUNTIF(B20:C20, E20)=0, 1, 0), 0) -> 0
A21: https://github.com/recharts/recharts/pull/6008#issuecomment-3004356312 | B21: Text Disappeared | D21: OutOfScope: Chromatic Error | F21: =IF(OR(AND(B21=D21, C21=E21), AND(B21=E21, C21=D21)), "ok", "conflict") -> conflict | G21: OutOfScope: Chromatic Error | I21: =IF(F21="ok",B21,G21) -> OutOfScope: Chromatic Error | J21: =IF(F21="ok",C21,H21) -> 0 | K21: =COUNTIF(D21:E21, B21) + IF(AND(C21<>"", C21<>B21), COUNTIF(D21:E21, C21), 0) -> 0 | L21: =IF(B21<>"", IF(COUNTIF(D21:E21, B21)=0, 1, 0), 0) + IF(AND(C21<>"", C21<>B21), IF(COUNTIF(D21:E21, C21)=0, 1, 0), 0) + IF(D21<>"", IF(COUNTIF(B21:C21, D21)=0, 1, 0), 0) + IF(AND(E21<>"", E21<>D21), IF(COUNTIF(B21:C21, E21)=0, 1, 0), 0) -> 2
A22: https://github.com/Khan/wonder-blocks/pull/2661#discussion_r2150341785 | B22: OutOfScope: New Story | D22: OutOfScope: New Story | F22: =IF(OR(AND(B22=D22, C22=E22), AND(B22=E22, C22=D22)), "ok", "conflict") -> ok | I22: =IF(F22="ok",B22,G22) -> OutOfScope: New Story | J22: =IF(F22="ok",C22,H22) -> 0 | K22: =COUNTIF(D22:E22, B22) + IF(AND(C22<>"", C22<>B22), COUNTIF(D22:E22, C22), 0) -> 1 | L22: =IF(B22<>"", IF(COUNTIF(D22:E22, B22)=0, 1, 0), 0) + IF(AND(C22<>"", C22<>B22), IF(COUNTIF(D22:E22, C22)=0, 1, 0), 0) + IF(D22<>"", IF(COUNTIF(B22:C22, D22)=0, 1, 0), 0) + IF(AND(E22<>"", E22<>D22), IF(COUNTIF(B22:C22, E22)=0, 1, 0), 0) -> 0
A23: https://github.com/coder/coder/pull/18445#discussion_r2157012512 | B23: Undefined/Wrong State is Shown | D23: Undefined/Wrong State is Shown | F23: =IF(OR(AND(B23=D23, C23=E23), AND(B23=E23, C23=D23)), "ok", "conflict") -> ok | I23: =IF(F23="ok",B23,G23) -> Undefined/Wrong State is Shown | J23: =IF(F23="ok",C23,H23) -> 0 | K23: =COUNTIF(D23:E23, B23) + IF(AND(C23<>"", C23<>B23), COUNTIF(D23:E23, C23), 0) -> 1 | L23: =IF(B23<>"", IF(COUNTIF(D23:E23, B23)=0, 1, 0), 0) + IF(AND(C23<>"", C23<>B23), IF(COUNTIF(D23:E23, C23)=0, 1, 0), 0) + IF(D23<>"", IF(COUNTIF(B23:C23, D23)=0, 1, 0), 0) + IF(AND(E23<>"", E23<>D23), IF(COUNTIF(B23:C23, E23)=0, 1, 0), 0) -> 0
A24: https://github.com/Esri/calcite-design-system/pull/12595#issuecomment-3134461611 | B24: Layout Shifted | D24: Layout Shifted | F24: =IF(OR(AND(B24=D24, C24=E24), AND(B24=E24, C24=D24)), "ok", "conflict") -> ok | I24: =IF(F24="ok",B24,G24) -> Layout Shifted | J24: =IF(F24="ok",C24,H24) -> 0 | K24: =COUNTIF(D24:E24, B24) + IF(AND(C24<>"", C24<>B24), COUNTIF(D24:E24, C24), 0) -> 1 | L24: =IF(B24<>"", IF(COUNTIF(D24:E24, B24)=0, 1, 0), 0) + IF(AND(C24<>"", C24<>B24), IF(COUNTIF(D24:E24, C24)=0, 1, 0), 0) + IF(D24<>"", IF(COUNTIF(B24:C24, D24)=0, 1, 0), 0) + IF(AND(E24<>"", E24<>D24), IF(COUNTIF(B24:C24, E24)=0, 1, 0), 0) -> 0
A25: https://github.com/kiva/kv-ui-elements/pull/597#issuecomment-3050388713 | B25: OutOfScope: Not VRT Discussion | D25: OutOfScope: Not VRT Discussion | F25: =IF(OR(AND(B25=D25, C25=E25), AND(B25=E25, C25=D25)), "ok", "conflict") -> ok | I25: =IF(F25="ok",B25,G25) -> OutOfScope: Not VRT Discussion | J25: =IF(F25="ok",C25,H25) -> 0 | K25: =COUNTIF(D25:E25, B25) + IF(AND(C25<>"", C25<>B25), COUNTIF(D25:E25, C25), 0) -> 1 | L25: =IF(B25<>"", IF(COUNTIF(D25:E25, B25)=0, 1, 0), 0) + IF(AND(C25<>"", C25<>B25), IF(COUNTIF(D25:E25, C25)=0, 1, 0), 0) + IF(D25<>"", IF(COUNTIF(B25:C25, D25)=0, 1, 0), 0) + IF(AND(E25<>"", E25<>D25), IF(COUNTIF(B25:C25, E25)=0, 1, 0), 0) -> 0
A26: https://github.com/Khan/perseus/pull/2728#discussion_r2226684249 | B26: OutOfScope: New Story | D26: OutOfScope: New Story | F26: =IF(OR(AND(B26=D26, C26=E26), AND(B26=E26, C26=D26)), "ok", "conflict") -> ok | I26: =IF(F26="ok",B26,G26) -> OutOfScope: New Story | J26: =IF(F26="ok",C26,H26) -> 0 | K26: =COUNTIF(D26:E26, B26) + IF(AND(C26<>"", C26<>B26), COUNTIF(D26:E26, C26), 0) -> 1 | L26: =IF(B26<>"", IF(COUNTIF(D26:E26, B26)=0, 1, 0), 0) + IF(AND(C26<>"", C26<>B26), IF(COUNTIF(D26:E26, C26)=0, 1, 0), 0) + IF(D26<>"", IF(COUNTIF(B26:C26, D26)=0, 1, 0), 0) + IF(AND(E26<>"", E26<>D26), IF(COUNTIF(B26:C26, E26)=0, 1, 0), 0) -> 0
A27: https://github.com/recharts/recharts/pull/6059#issuecomment-3037435884 | B27: Layout Shifted | C27: New Contents | D27: New Contents | E27: Layout Shifted | F27: =IF(OR(AND(B27=D27, C27=E27), AND(B27=E27, C27=D27)), "ok", "conflict") -> ok | I27: =IF(F27="ok",B27,G27) -> Layout Shifted | J27: =IF(F27="ok",C27,H27) -> New Contents | K27: =COUNTIF(D27:E27, B27) + IF(AND(C27<>"", C27<>B27), COUNTIF(D27:E27, C27), 0) -> 2 | L27: =IF(B27<>"", IF(COUNTIF(D27:E27, B27)=0, 1, 0), 0) + IF(AND(C27<>"", C27<>B27), IF(COUNTIF(D27:E27, C27)=0, 1, 0), 0) + IF(D27<>"", IF(COUNTIF(B27:C27, D27)=0, 1, 0), 0) + IF(AND(E27<>"", E27<>D27), IF(COUNTIF(B27:C27, E27)=0, 1, 0), 0) -> 0
A28: https://github.com/Khan/wonder-blocks/pull/2715#issuecomment-3104643517 | B28: Layout Shifted | D28: Layout Shifted | F28: =IF(OR(AND(B28=D28, C28=E28), AND(B28=E28, C28=D28)), "ok", "conflict") -> ok | I28: =IF(F28="ok",B28,G28) -> Layout Shifted | J28: =IF(F28="ok",C28,H28) -> 0 | K28: =COUNTIF(D28:E28, B28) + IF(AND(C28<>"", C28<>B28), COUNTIF(D28:E28, C28), 0) -> 1 | L28: =IF(B28<>"", IF(COUNTIF(D28:E28, B28)=0, 1, 0), 0) + IF(AND(C28<>"", C28<>B28), IF(COUNTIF(D28:E28, C28)=0, 1, 0), 0) + IF(D28<>"", IF(COUNTIF(B28:C28, D28)=0, 1, 0), 0) + IF(AND(E28<>"", E28<>D28), IF(COUNTIF(B28:C28, E28)=0, 1, 0), 0) -> 0
A29: https://github.com/Khan/wonder-blocks/pull/2766#discussion_r2294739847 | B29: Box Color Changed | D29: Box Color Changed | F29: =IF(OR(AND(B29=D29, C29=E29), AND(B29=E29, C29=D29)), "ok", "conflict") -> ok | I29: =IF(F29="ok",B29,G29) -> Box Color Changed | J29: =IF(F29="ok",C29,H29) -> 0 | K29: =COUNTIF(D29:E29, B29) + IF(AND(C29<>"", C29<>B29), COUNTIF(D29:E29, C29), 0) -> 1 | L29: =IF(B29<>"", IF(COUNTIF(D29:E29, B29)=0, 1, 0), 0) + IF(AND(C29<>"", C29<>B29), IF(COUNTIF(D29:E29, C29)=0, 1, 0), 0) + IF(D29<>"", IF(COUNTIF(B29:C29, D29)=0, 1, 0), 0) + IF(AND(E29<>"", E29<>D29), IF(COUNTIF(B29:C29, E29)=0, 1, 0), 0) -> 0
A30: https://github.com/Khan/wonder-blocks/pull/2758#discussion_r2279534507 | B30: Border Color Changed | D30: Border Color Changed | F30: =IF(OR(AND(B30=D30, C30=E30), AND(B30=E30, C30=D30)), "ok", "conflict") -> ok | I30: =IF(F30="ok",B30,G30) -> Border Color Changed | J30: =IF(F30="ok",C30,H30) -> 0 | K30: =COUNTIF(D30:E30, B30) + IF(AND(C30<>"", C30<>B30), COUNTIF(D30:E30, C30), 0) -> 1 | L30: =IF(B30<>"", IF(COUNTIF(D30:E30, B30)=0, 1, 0), 0) + IF(AND(C30<>"", C30<>B30), IF(COUNTIF(D30:E30, C30)=0, 1, 0), 0) + IF(D30<>"", IF(COUNTIF(B30:C30, D30)=0, 1, 0), 0) + IF(AND(E30<>"", E30<>D30), IF(COUNTIF(B30:C30, E30)=0, 1, 0), 0) -> 0
